----------------------_handle_commands----------------------
Traceback (most recent call last):
  File "/Users/user/Library/Application Support/hatch/env/virtual/dafi/Vjr0VuTJ/dafi/lib/python3.10/site-packages/anyio/_backends/_asyncio.py", line 1373, in receive
    data = self.__raw_socket.recv(max_bytes)
BlockingIOError: [Errno 35] Resource temporarily unavailable

During handling of the above exception, another exception occurred:

Traceback (most recent call last):
  File "/Users/user/Documents/InvestigatedLibraries/dafi/dafi/components/controller.py", line 71, in _handle_commands
    raw_msglen = await stream.receive(4)
  File "/Users/user/Library/Application Support/hatch/env/virtual/dafi/Vjr0VuTJ/dafi/lib/python3.10/site-packages/anyio/_backends/_asyncio.py", line 1375, in receive
    await self._wait_until_readable(loop)
asyncio.exceptions.CancelledError

During handling of the above exception, another exception occurred:

Traceback (most recent call last):
  File "/Users/user/Documents/InvestigatedLibraries/dafi/dafi/utils/debug.py", line 14, in write_exception_trace
    retry_state.outcome.result()
  File "/opt/homebrew/Cellar/python@3.10/3.10.6_2/Frameworks/Python.framework/Versions/3.10/lib/python3.10/concurrent/futures/_base.py", line 451, in result
    return self.__get_result()
  File "/opt/homebrew/Cellar/python@3.10/3.10.6_2/Frameworks/Python.framework/Versions/3.10/lib/python3.10/concurrent/futures/_base.py", line 403, in __get_result
    raise self._exception
  File "/Users/user/Library/Application Support/hatch/env/virtual/dafi/Vjr0VuTJ/dafi/lib/python3.10/site-packages/tenacity/_asyncio.py", line 51, in __call__
    result = await fn(*args, **kwargs)
  File "/Users/user/Documents/InvestigatedLibraries/dafi/dafi/components/controller.py", line 68, in _handle_commands
    async with stream:
  File "/Users/user/Library/Application Support/hatch/env/virtual/dafi/Vjr0VuTJ/dafi/lib/python3.10/site-packages/anyio/abc/_resources.py", line 25, in __aexit__
    await self.aclose()
  File "/Users/user/Library/Application Support/hatch/env/virtual/dafi/Vjr0VuTJ/dafi/lib/python3.10/site-packages/anyio/_backends/_asyncio.py", line 1488, in aclose
    self._send_future.set_result(None)
asyncio.exceptions.InvalidStateError: invalid state
